<?xml version="1.0" ?>
<!-- =================================================================================== -->
<!-- |    This document was autogenerated by xacro from /home/igor/ws/src/kawasaki/kawasaki_description/urdf/fs03n/xfs03n.urdf.xacro | -->
<!-- |    EDITING THIS FILE BY HAND IS NOT RECOMMENDED                                 | -->
<!-- =================================================================================== -->
<robot name="fs03n" xmlns:xacro="http://www.ros.org/wiki/xacro">
  <gazebo>
    <plugin filename="libgazebo_ros_control.so" name="ros_control">
      <robotNamespace>/bimanous</robotNamespace>
      <!--robotSimType>gazebo_ros_control/DefaultRobotHWSim</robotSimType-->
    </plugin>
  </gazebo>
  <material name="IPA/LightGrey">
    <color rgba="0.7 0.7 0.7 1.0"/>
  </material>
  <material name="IPA/DarkGrey">
    <color rgba="0.4 0.4 0.4 1.0"/>
  </material>
  <material name="IPA/Orange">
    <color rgba="1.0 0.4 0.0 1.0"/>
  </material>
  <material name="IPA/Black">
    <color rgba="0.0 0.0 0.0 1.0"/>
  </material>
  <material name="IPA/Blue">
    <color rgba="0.0 0.0 0.5 1.0"/>
  </material>
  <material name="Kawasaki/LightGrey">
    <color rgba="0.7 0.7 0.7 1.0"/>
  </material>
  <link name="world"/>
  <joint name="base_joint" type="fixed">
    <parent link="world"/>
    <child link="base_link"/>
    <origin rpy="0 0 0" xyz="0 0 0"/>
  </joint>
  <link name="base_link">
    <visual>
      <geometry>
        <mesh filename="package://kawasaki_description/meshes/fs03n/visual/base_link.STL"/>
      </geometry>
      <material name="Kawasaki/LightGrey"/>
    </visual>
    <collision>
      <geometry>
        <mesh filename="package://kawasaki_description/meshes/fs03n/collision/base_link.STL"/>
      </geometry>
    </collision>
    <inertial>
      <mass value="0.1"/>
      <origin rpy="0 0 0" xyz="0 0 0"/>
      <inertia ixx="0" ixy="0" ixz="0" iyy="0" iyz="0" izz="0"/>
    </inertial>
  </link>
  <link name="link_1">
    <visual>
      <geometry>
        <mesh filename="package://kawasaki_description/meshes/fs03n/visual/link_1.STL"/>
      </geometry>
      <material name="Kawasaki/LightGrey"/>
    </visual>
    <collision>
      <geometry>
        <mesh filename="package://kawasaki_description/meshes/fs03n/collision/link_1.STL"/>
      </geometry>
    </collision>
    <inertial>
      <mass value="0.1"/>
      <origin rpy="0 0 0" xyz="0 0 0"/>
      <inertia ixx="0" ixy="0" ixz="0" iyy="0" iyz="0" izz="0"/>
    </inertial>
  </link>
  <link name="link_2">
    <visual>
      <geometry>
        <mesh filename="package://kawasaki_description/meshes/fs03n/visual/link_2.STL"/>
      </geometry>
      <material name="Kawasaki/LightGrey"/>
    </visual>
    <collision>
      <geometry>
        <mesh filename="package://kawasaki_description/meshes/fs03n/collision/link_2.STL"/>
      </geometry>
    </collision>
    <inertial>
      <mass value="0.1"/>
      <origin rpy="0 0 0" xyz="0 0 0"/>
      <inertia ixx="0" ixy="0" ixz="0" iyy="0" iyz="0" izz="0"/>
    </inertial>
  </link>
  <link name="link_3">
    <visual>
      <geometry>
        <mesh filename="package://kawasaki_description/meshes/fs03n/visual/link_3.STL"/>
      </geometry>
      <material name="Kawasaki/LightGrey"/>
    </visual>
    <collision>
      <geometry>
        <mesh filename="package://kawasaki_description/meshes/fs03n/collision/link_3.STL"/>
      </geometry>
    </collision>
    <inertial>
      <mass value="0.1"/>
      <origin rpy="0 0 0" xyz="0 0 0"/>
      <inertia ixx="0" ixy="0" ixz="0" iyy="0" iyz="0" izz="0"/>
    </inertial>
  </link>
  <link name="link_4">
    <visual>
      <geometry>
        <mesh filename="package://kawasaki_description/meshes/fs03n/visual/link_4.STL"/>
      </geometry>
      <material name="Kawasaki/LightGrey"/>
    </visual>
    <collision>
      <geometry>
        <mesh filename="package://kawasaki_description/meshes/fs03n/collision/link_4.STL"/>
      </geometry>
    </collision>
    <inertial>
      <mass value="0.1"/>
      <origin rpy="0 0 0" xyz="0 0 0"/>
      <inertia ixx="0" ixy="0" ixz="0" iyy="0" iyz="0" izz="0"/>
    </inertial>
  </link>
  <link name="link_5">
    <visual>
      <geometry>
        <mesh filename="package://kawasaki_description/meshes/fs03n/visual/link_5.STL"/>
      </geometry>
      <material name="Kawasaki/LightGrey"/>
    </visual>
    <collision>
      <geometry>
        <mesh filename="package://kawasaki_description/meshes/fs03n/collision/link_5.STL"/>
      </geometry>
    </collision>
    <inertial>
      <mass value="0.1"/>
      <origin rpy="0 0 0" xyz="0 0 0"/>
      <inertia ixx="0" ixy="0" ixz="0" iyy="0" iyz="0" izz="0"/>
    </inertial>
  </link>
  <link name="link_6">
    <visual>
      <geometry>
        <mesh filename="package://kawasaki_description/meshes/fs03n/visual/link_6.STL"/>
      </geometry>
      <material name="Kawasaki/LightGrey"/>
    </visual>
    <!--collision>
				<geometry>
					<mesh filename="package://kawasaki_description/meshes/fs03n/collision/link_6.STL" />
				</geometry>
			</collision-->
    <inertial>
      <mass value="0.1"/>
      <origin rpy="0 0 0" xyz="0 0 0"/>
      <inertia ixx="0" ixy="0" ixz="0" iyy="0" iyz="0" izz="0"/>
    </inertial>
  </link>
  <link name="tool">
		</link>
  <joint name="JT1" type="revolute">
    <parent link="base_link"/>
    <child link="link_1"/>
    <origin rpy="0 0 0" xyz="0 0 0.25"/>
    <axis xyz="0 0 -1"/>
    <limit effort="100" lower="-2.7925268032" upper="2.7925268032" velocity="1.25663706144"/>
    <safety_controller k_position="20" k_velocity="50" soft_lower_limit="-2.7052603406" soft_upper_limit="2.7052603406"/>
  </joint>
  <joint name="JT2" type="revolute">
    <parent link="link_1"/>
    <child link="link_2"/>
    <origin rpy="0 0 0" xyz="0 0.12 0"/>
    <axis xyz="-1 0 0"/>
    <limit effort="100" lower="-1.0471975512" upper="2.617993878" velocity="0.872664626"/>
    <safety_controller k_position="20" k_velocity="50" soft_lower_limit="-0.9599310886" soft_upper_limit="2.5307274154"/>
  </joint>
  <joint name="JT3" type="revolute">
    <parent link="link_2"/>
    <child link="link_3"/>
    <origin rpy="0 0 0" xyz="0 0 0.25"/>
    <axis xyz="1 0 0"/>
    <limit effort="100" lower="-2.617993878" upper="2.0943951024" velocity="0.7853981634"/>
    <safety_controller k_position="20" k_velocity="50" soft_lower_limit="-2.5307274154" soft_upper_limit="2.0071286398"/>
  </joint>
  <joint name="JT4" type="revolute">
    <parent link="link_3"/>
    <child link="link_4"/>
    <origin rpy="0 0 0" xyz="0 0 0"/>
    <axis xyz="0 0 1"/>
    <limit effort="100" lower="-3.1415926536" upper="3.1415926536" velocity="1.88495559216"/>
    <safety_controller k_position="20" k_velocity="50" soft_lower_limit="-3.054326191" soft_upper_limit="3.054326191"/>
  </joint>
  <joint name="JT5" type="revolute">
    <parent link="link_4"/>
    <child link="link_5"/>
    <origin rpy="0 0 0" xyz="0 0 0.25"/>
    <axis xyz="1 0 0"/>
    <limit effort="100" lower="-2.3561944902" upper="2.3561944902" velocity="0.7853981634"/>
    <safety_controller k_position="20" k_velocity="50" soft_lower_limit="-2.2689280276" soft_upper_limit="2.2689280276"/>
  </joint>
  <joint name="JT6" type="revolute">
    <parent link="link_5"/>
    <child link="link_6"/>
    <origin rpy="0 0 0" xyz="0 0 0.08"/>
    <axis xyz="0 0 1"/>
    <limit effort="100" lower="-3.1415926536" upper="3.1415926536" velocity="1.88495559216"/>
    <safety_controller k_position="20" k_velocity="50" soft_lower_limit="-3.1415926536" soft_upper_limit="3.1415926536"/>
    <!--limit lower="${-360 * deg2rad}" upper="${360 * deg2rad}" velocity="${540*speed_limit * deg2rad}" effort="${effort}" />
			<safety_controller soft_lower_limit="${-355 * deg2rad}" soft_upper_limit="${355 * deg2rad}" k_position="20" k_velocity="50" /-->
  </joint>
  <joint name="jtool0" type="fixed">
    <parent link="link_6"/>
    <child link="tool"/>
    <origin rpy="0 0 0" xyz="0 0 0"/>
  </joint>
  <gazebo reference="base_link">
    <material>Gazebo/Grey</material>
    <turnGravityOff>true</turnGravityOff>
  </gazebo>
  <gazebo reference="link_1">
    <material>Gazebo/Grey</material>
    <turnGravityOff>true</turnGravityOff>
  </gazebo>
  <gazebo reference="link_2">
    <material>Gazebo/Grey</material>
    <turnGravityOff>true</turnGravityOff>
  </gazebo>
  <gazebo reference="link_3">
    <material>Gazebo/Grey</material>
    <turnGravityOff>true</turnGravityOff>
  </gazebo>
  <gazebo reference="link_4">
    <material>Gazebo/Grey</material>
    <turnGravityOff>true</turnGravityOff>
  </gazebo>
  <gazebo reference="link_5">
    <material>Gazebo/Grey</material>
    <turnGravityOff>true</turnGravityOff>
  </gazebo>
  <gazebo reference="link_6">
    <material>Gazebo/Grey</material>
    <turnGravityOff>true</turnGravityOff>
  </gazebo>
  <transmission name="JT1_trans">
    <type>transmission_interface/SimpleTransmission</type>
    <joint name="JT1"/>
    <actuator name="JT1_motor">
      <hardwareInterface>EffortJointInterface</hardwareInterface>
      <mechanicalReduction>1</mechanicalReduction>
    </actuator>
  </transmission>
  <transmission name="JT2_trans">
    <type>transmission_interface/SimpleTransmission</type>
    <joint name="JT2"/>
    <actuator name="JT2_motor">
      <hardwareInterface>EffortJointInterface</hardwareInterface>
      <mechanicalReduction>1</mechanicalReduction>
    </actuator>
  </transmission>
  <transmission name="JT3_trans">
    <type>transmission_interface/SimpleTransmission</type>
    <joint name="JT3"/>
    <actuator name="JT3_motor">
      <hardwareInterface>EffortJointInterface</hardwareInterface>
      <mechanicalReduction>1</mechanicalReduction>
    </actuator>
  </transmission>
  <transmission name="JT4_trans">
    <type>transmission_interface/SimpleTransmission</type>
    <joint name="JT4"/>
    <actuator name="JT4_motor">
      <hardwareInterface>EffortJointInterface</hardwareInterface>
      <mechanicalReduction>1</mechanicalReduction>
    </actuator>
  </transmission>
  <transmission name="JT5_trans">
    <type>transmission_interface/SimpleTransmission</type>
    <joint name="JT5"/>
    <actuator name="JT5_motor">
      <hardwareInterface>EffortJointInterface</hardwareInterface>
      <mechanicalReduction>1</mechanicalReduction>
    </actuator>
  </transmission>
  <transmission name="JT6_trans">
    <type>transmission_interface/SimpleTransmission</type>
    <joint name="JT6"/>
    <actuator name="JT6_motor">
      <hardwareInterface>EffortJointInterface</hardwareInterface>
      <mechanicalReduction>1</mechanicalReduction>
    </actuator>
  </transmission>
</robot>
