<?xml version="1.0" ?>
<robot xmlns:xacro="http://ros.org/wiki/xacro">
	
	<!--xacro:include filename="$(find kawasaki_description)/urdf/materials.urdf.xacro" /-->
	<xacro:include filename="$(find kawasaki_description)/urdf/fs03n/fs03n.gazebo.xacro" />
	<xacro:include filename="$(find kawasaki_description)/urdf/fs03n/fs03n.transmission.xacro" />
	
	<xacro:property name="deg2rad" value="0.01745329252" />
	<xacro:property name="speed_limit" value="0.4" />
	<!-- 20% of maximum speed -->
	<xacro:property name="effort" value="100" />
	
	<xacro:macro name="kawasaki_fs03n" params="prefix parent *origin">
		
		<joint name="${prefix}base_joint" type="fixed">
			<parent link="${parent}"/>
			<child link="${prefix}base_link"/>
			<insert_block name="origin" />
		</joint>
		
		<!-- link list -->
		<link name="${prefix}base_link">
			<visual>	
				<geometry>
					<mesh filename="package://kawasaki_description/meshes/fs03n/visual/base_link.STL" />
				</geometry>
				<material name="Kawasaki/LightGrey"/>
			</visual>
			<collision>
				<geometry>
					<mesh filename="package://kawasaki_description/meshes/fs03n/collision/base_link.STL" />
				</geometry>
			</collision>
			<inertial>
				<mass value="0.1" />
				<origin xyz="0 0 0" rpy="0 0 0"/>
				<inertia ixx="0" ixy="0" ixz="0" iyy="0" iyz="0" izz="0" />
			</inertial>
		</link>
		<link name="${prefix}link_1">
			<visual>
				<geometry>
					<mesh filename="package://kawasaki_description/meshes/fs03n/visual/link_1.STL" />
				</geometry>
				<material name="Kawasaki/LightGrey"/>
			</visual>
			<collision>
				<geometry>
					<mesh filename="package://kawasaki_description/meshes/fs03n/collision/link_1.STL" />
				</geometry>
			</collision>
			<inertial>
				<mass value="0.1" />
				<origin xyz="0 0 0" rpy="0 0 0"/>
				<inertia ixx="0" ixy="0" ixz="0" iyy="0" iyz="0" izz="0" />
			</inertial>
		</link>
		<link name="${prefix}link_2">
			<visual>
				<geometry>
					<mesh filename="package://kawasaki_description/meshes/fs03n/visual/link_2.STL" />
				</geometry>
				<material name="Kawasaki/LightGrey"/>
			</visual>
			<collision>
				<geometry>
					<mesh filename="package://kawasaki_description/meshes/fs03n/collision/link_2.STL" />
				</geometry>
			</collision>
			<inertial>
				<mass value="0.1" />
				<origin xyz="0 0 0" rpy="0 0 0"/>
				<inertia ixx="0" ixy="0" ixz="0" iyy="0" iyz="0" izz="0" />
			</inertial>
		</link>
		<link name="${prefix}link_3">
			<visual>
				<geometry>
					<mesh filename="package://kawasaki_description/meshes/fs03n/visual/link_3.STL" />
				</geometry>
				<material name="Kawasaki/LightGrey"/>
			</visual>
			<collision>
				<geometry>
					<mesh filename="package://kawasaki_description/meshes/fs03n/collision/link_3.STL" />
				</geometry>
			</collision>
			<inertial>
				<mass value="0.1" />
				<origin xyz="0 0 0" rpy="0 0 0"/>
				<inertia ixx="0" ixy="0" ixz="0" iyy="0" iyz="0" izz="0" />
			</inertial>
		</link>
		<link name="${prefix}link_4">
			<visual>
				<geometry>
					<mesh filename="package://kawasaki_description/meshes/fs03n/visual/link_4.STL" />
				</geometry>
				<material name="Kawasaki/LightGrey"/>
			</visual>
			<collision>
				<geometry>
					<mesh filename="package://kawasaki_description/meshes/fs03n/collision/link_4.STL" />
				</geometry>
			</collision>
			<inertial>
				<mass value="0.1" />
				<origin xyz="0 0 0" rpy="0 0 0"/>
				<inertia ixx="0" ixy="0" ixz="0" iyy="0" iyz="0" izz="0" />
			</inertial>
		</link>
		<link name="${prefix}link_5">
			<visual>
				<geometry>
					<mesh filename="package://kawasaki_description/meshes/fs03n/visual/link_5.STL" />
				</geometry>
				<material name="Kawasaki/LightGrey"/>
			</visual>
			<collision>
				<geometry>
					<mesh filename="package://kawasaki_description/meshes/fs03n/collision/link_5.STL" />
				</geometry>
			</collision>
			<inertial>
				<mass value="0.1" />
				<origin xyz="0 0 0" rpy="0 0 0"/>
				<inertia ixx="0" ixy="0" ixz="0" iyy="0" iyz="0" izz="0" />
			</inertial>
		</link>
		<link name="${prefix}link_6">
			<visual>
				<geometry>
					<mesh filename="package://kawasaki_description/meshes/fs03n/visual/link_6.STL" />
				</geometry>
				<material name="Kawasaki/LightGrey"/>
			</visual>
			<!--collision>
				<geometry>
					<mesh filename="package://kawasaki_description/meshes/fs03n/collision/link_6.STL" />
				</geometry>
			</collision-->
			<inertial>
				<mass value="0.1" />
				<origin xyz="0 0 0" rpy="0 0 0"/>
				<inertia ixx="0" ixy="0" ixz="0" iyy="0" iyz="0" izz="0" />
			</inertial>
		</link>
		<link name="${prefix}tool">
		</link>
		<!-- end of link list -->
		<!-- joint list -->
		<joint name="${prefix}JT1" type="revolute">
			<parent link="${prefix}base_link"/>
			<child link="${prefix}link_1"/>
			<origin xyz="0 0 0.25" rpy="0 0 0" />
			<axis xyz="0 0 -1" />
			<limit lower="${-160 * deg2rad}" upper="${160 * deg2rad}" velocity="${360*speed_limit * deg2rad}" effort="${effort}" />
			<safety_controller soft_lower_limit="${-155 * deg2rad}" soft_upper_limit="${155 * deg2rad}" k_position="20" k_velocity="50" />			
		</joint>
		<joint name="${prefix}JT2" type="revolute">
			<parent link="${prefix}link_1"/>
			<child link="${prefix}link_2"/>
			<origin xyz="0 0.12 0" rpy="0 0 0" />
			<axis xyz="-1 0 0" />
			<limit lower="${-60 * deg2rad}" upper="${150 * deg2rad}" velocity="${250*speed_limit * deg2rad}" effort="${effort}" />
			<safety_controller soft_lower_limit="${-55 * deg2rad}" soft_upper_limit="${145 * deg2rad}" k_position="20" k_velocity="50" />			
		</joint>
		<joint name="${prefix}JT3" type="revolute">
			<parent link="${prefix}link_2"/>
			<child link="${prefix}link_3"/>
			<origin xyz="0 0 0.25" rpy="0 0 0" />
			<axis xyz="1 0 0" />
			<limit lower="${-150 * deg2rad}" upper="${120 * deg2rad}" velocity="${225*speed_limit * deg2rad}" effort="${effort}" />
			<safety_controller soft_lower_limit="${-145 * deg2rad}" soft_upper_limit="${115 * deg2rad}" k_position="20" k_velocity="50" />			
		</joint>
		<joint name="${prefix}JT4" type="revolute">
			<parent link="${prefix}link_3"/>
			<child link="${prefix}link_4"/>
			<origin xyz="0 0 0" rpy="0 0 0" />
			<axis xyz="0 0 1" />
			<limit lower="${-180 * deg2rad}" upper="${180 * deg2rad}" velocity="${540*speed_limit * deg2rad}" effort="${effort}" />
			<safety_controller soft_lower_limit="${-175 * deg2rad}" soft_upper_limit="${175 * deg2rad}" k_position="20" k_velocity="50" />			
		</joint>
		<joint name="${prefix}JT5" type="revolute">
			<parent link="${prefix}link_4"/>
			<child link="${prefix}link_5"/>
			<origin xyz="0 0 0.25" rpy="0 0 0" />
			<axis xyz="1 0 0" />
			<!-- 
			<limit lower="${-135 * deg2rad}" upper="${135 * deg2rad}" velocity="${225*speed_limit * deg2rad}" effort="${effort}" />
			<safety_controller soft_lower_limit="${-130 * deg2rad}" soft_upper_limit="${130 * deg2rad}" k_position="20" k_velocity="50" />
			-->		
			<limit lower="${-120 * deg2rad}" upper="${95 * deg2rad}" velocity="${225*speed_limit * deg2rad}" effort="${effort}" />
			<safety_controller soft_lower_limit="${-115 * deg2rad}" soft_upper_limit="${90 * deg2rad}" k_position="20" k_velocity="50" />	
		</joint>
		<joint name="${prefix}JT6" type="revolute">
			<parent link="${prefix}link_5"/>
			<child link="${prefix}link_6"/>
			<origin xyz="0 0 0.08" rpy="0 0 0" />
			<axis xyz="0 0 1" />
			<limit lower="${-180 * deg2rad}" upper="${180 * deg2rad}" velocity="${540*speed_limit * deg2rad}" effort="${effort}" />
			<safety_controller soft_lower_limit="${-180 * deg2rad}" soft_upper_limit="${180 * deg2rad}" k_position="20" k_velocity="50" />			
			<!--limit lower="${-360 * deg2rad}" upper="${360 * deg2rad}" velocity="${540*speed_limit * deg2rad}" effort="${effort}" />
			<safety_controller soft_lower_limit="${-355 * deg2rad}" soft_upper_limit="${355 * deg2rad}" k_position="20" k_velocity="50" /-->
		</joint>
		<joint name="${prefix}jtool0" type="fixed">
			<parent link="${prefix}link_6"/>
			<child link="${prefix}tool"/>
			<origin xyz="0 0 0" rpy="0 0 0" />
		</joint>
		<!-- end of joint list -->
		
		<!-- extensions -->
		<xacro:kawasaki_fs03n_gazebo prefix="${prefix}" />
		<xacro:kawasaki_fs03n_transmission prefix="${prefix}" />
		
	</xacro:macro>
</robot>
