<?xml version="1.0"?>
<robot name="egn_160">

 <!-- ADAPTER LINK -->
 <link name="adapter_link">
      <inertial>
          <mass value="1.2" />
          <origin xyz="0 0 0" />
      	  <inertia  ixx="1.0" ixy="0.0"  ixz="0.0"  iyy="1.0"  iyz="0.0"  izz="1.0" />
      </inertial>

      <visual>
          <origin xyz="0.0 0.0 0.0" rpy="0.0 0.0 0.0" />
          <geometry>
             <mesh filename="package://schunk_egn160_description/meshes/adapter.stl" scale="0.001 0.001 0.001"/>
          </geometry>
          <material name="blue">
		<color rgba="0 0 1 1"/>
      	  </material>
      </visual>

      <collision>
          <origin xyz="0.0 0.0 0.0" rpy="0.0 0.0 0.0" />
          <geometry>
             <mesh filename="package://schunk_egn160_description/meshes/adapter.stl" scale="0.001 0.001 0.001"/>
         </geometry>
     </collision>
  </link>
  
  <!-- BASE LINK -->
 <link name="base_link">
      <inertial>
          <mass value="1.2" />
          <origin xyz="0 0 0" />
      	  <inertia  ixx="1.0" ixy="0.0"  ixz="0.0"  iyy="1.0"  iyz="0.0"  izz="1.0" />
      </inertial>

      <visual>
          <origin xyz="0.0 0.0 0.0" rpy="0.0 0.0 0.0" />
          <geometry>
             <mesh filename="package://schunk_egn160_description/meshes/base.stl" scale="1 1 1"/>
          </geometry>
          <material name="grey">
		<color rgba="0.5 0.5 0.5 1"/>
      	  </material>
      </visual>

      <collision>
          <origin xyz="0.0 0.0 0.0" rpy="0.0 0.0 0.0" />
          <geometry>
             <mesh filename="package://schunk_egn160_description/meshes/base.stl" scale="1 1 1"/>
         </geometry>
     </collision>
  </link>
  
 <!-- PALM LINK -->
 <link name="palm_link">
      <inertial>
          <mass value="1.2" />
          <origin xyz="0 0 0" />
      	  <inertia  ixx="1.0" ixy="0.0"  ixz="0.0"  iyy="1.0"  iyz="0.0"  izz="1.0" />
      </inertial>

      <visual>
          <origin xyz="0.0 0.0 0.0" rpy="0.0 0.0 0.0" />
          <geometry>
             <mesh filename="package://schunk_egn160_description/meshes/palm.stl" scale="1 1 1"/>
          </geometry>
          <material name="grey">
		<color rgba="0.5 0.5 0.5 1"/>
      	  </material>
      </visual>

      <collision>
          <origin xyz="0.0 0.0 0.0" rpy="0.0 0.0 0.0" />
          <geometry>
             <mesh filename="package://schunk_egn160_description/meshes/palm.stl" scale="1 1 1"/>
         </geometry>
     </collision>
  </link>
  
  <!-- GRIPPER LEFT -->
  <link name="gripper_left">
      <inertial>
          <mass value="0.1" />
          <origin xyz="0 0 0" />
      <inertia ixx="1.0" ixy="0.0" ixz="0.0"
               iyy="1.0" iyz="0.0" 
               izz="1.0" />
      </inertial>

      <visual>
          <origin xyz="0.0 0 0" rpy="0 0 0" />
          <geometry>
             <mesh filename="package://schunk_egn160_description/meshes/gripper.stl" scale="1 1 1"/>
          </geometry>
          <material name="black">
		<color rgba="0 0 0 1"/>
      	  </material>
      </visual>

      <collision>
          <origin xyz="0 0 0" rpy="0 0 0" />
          <geometry>
             <mesh filename="package://schunk_egn160_description/meshes/gripper.stl" scale="1 1 1"/>
         </geometry>
     </collision>
  </link>
  
  <!-- FINGER LEFT -->
  <link name="finger_left">
      <inertial>
          <mass value="0.1" />
          <origin xyz="0 0 0" />
      <inertia ixx="1.0" ixy="0.0" ixz="0.0"
               iyy="1.0" iyz="0.0" 
               izz="1.0" />
      </inertial>

      <visual>
          <origin xyz="0.0 0.0 0.037" rpy="0 0 0" />
          <geometry>
             <mesh filename="package://schunk_egn160_description/meshes/finger.stl" scale="1 1 1"/>
          </geometry>
          <material name="blue">
		<color rgba="0 0 1 1"/>
      	  </material>
      </visual>

      <collision>
          <origin xyz="0.0 0.0 0.037" rpy="0 0 0" />
          <geometry>
             <mesh filename="package://schunk_egn160_description/meshes/finger.stl" scale="1 1 1"/>
         </geometry>
     </collision>
  </link>
  
  <!-- GRIPPER RIGHT -->
  <link name="gripper_right">
      <inertial>
          <mass value="0.1" />
          <origin xyz="0 0 0" />
      <inertia ixx="1.0" ixy="0.0" ixz="0.0"
               iyy="1.0" iyz="0.0" 
               izz="1.0" />
      </inertial>

      <visual>
          <origin xyz="0.0 0.0 0.0" rpy="0 0 0" />
          <geometry>
             <mesh filename="package://schunk_egn160_description/meshes/gripper.stl" scale="1 1 1"/>
          </geometry>
          <material name="black">
		<color rgba="0 0 0 1"/>
      	  </material>
      </visual>

      <collision>
          <origin xyz="0.0 0.0 0.0" rpy="0 0 0" />
          <geometry>
             <mesh filename="package://schunk_egn160_description/meshes/gripper.stl" scale="1 1 1"/>
         </geometry>
     </collision>
  </link>
  
  <!-- FINGER RIGHT -->
  <link name="finger_right">
      <inertial>
          <mass value="0.1" />
          <origin xyz="0 0 0" />
      <inertia ixx="1.0" ixy="0.0" ixz="0.0"
               iyy="1.0" iyz="0.0" 
               izz="1.0" />
      </inertial>

      <visual>
          <origin xyz="0.0 0.0 0.037" rpy="0 0 0" />
          <geometry>
             <mesh filename="package://schunk_egn160_description/meshes/finger.stl" scale="1 1 1"/>
          </geometry>
          <material name="blue">
		<color rgba="0 0 1 1"/>
      	  </material>
      </visual>

      <collision>
          <origin xyz="0.0 0.0 0.037" rpy="0 0 0" />
          <geometry>
             <mesh filename="package://schunk_egn160_description/meshes/finger.stl" scale="1 1 1"/>
         </geometry>
      </collision>
  </link>

  <!-- JOINTS -->
  <joint name="adapter_joint_base" type="fixed">
     <origin xyz="0 0 0.015" rpy="0 0 0" />
     <parent link="adapter_link"/>
     <child link="base_link" />
  </joint>
  
  <joint name="base_joint_palm" type="fixed">
     <origin xyz="0 0 0.21" rpy="0 0 0" />
     <parent link="base_link"/>
     <child link="palm_link" />
  </joint>
  
  <joint name="palm_joint_gripper_left" type="prismatic">
     <limit lower="0" upper="0.016" effort="1.0" velocity="1.0"/>
     <origin xyz="0 -0.0545 0.064" rpy="0 0 3.14159" />      
     <parent link="palm_link"/>
     <child link="gripper_left" />
     <dynamics friction="100" damping="100" />
     <axis xyz="0 1 0"/>
     <limit effort="100" velocity="100"/>
     <mimic joint="palm_joint_gripper_right" multiplier="1.0" offset="0.0"/> 
  </joint>

  <joint name="gripper_joint_finger_left" type="fixed">
     <origin xyz="0 0 0" rpy="0 0 0" />
     <parent link="gripper_left"/>
     <child link="finger_left" />
     <dynamics friction="100" damping="100" />
     <axis xyz="1 0 0"/>
     <limit effort="100" velocity="100"/>
  </joint>
  
  <joint name="palm_joint_gripper_right" type="prismatic">
     <limit lower="0" upper="0.016" effort="1.0" velocity="1.0"/>
     <origin xyz="0 0.0545 0.064" rpy="0 0 0" />
     <parent link="palm_link"/>
     <child link="gripper_right" />
     <axis xyz="0 1 0"/>
     <dynamics friction="100" damping="100" />
     <limit effort="100" velocity="100"/>
  </joint>
  
  <joint name="gripper_joint_finger_right" type="fixed">
     <origin xyz="0 0 0" rpy="0 0 0" />
     <parent link="gripper_right"/>
     <child link="finger_right" />
     <dynamics friction="100" damping="100" />
     <axis xyz="1 0 0"/>
     <limit effort="100" velocity="100"/>
  </joint>

</robot>


